Workbook

Sheet Items
A1: ID | B1: Tier | C1: Category | D1: Item | E1: Specification | F1: Qty | G1: Ref. price | H1: Cur. | I1: Unit, USD | J1: Ext., USD | K1: Unit, KWD | L1: Ext., KWD | M1: Status | N1: Price basis | O1: Reference vendor | P1: Reference URL | Q1: Checked | R1: Checked via | S1: Need by | T1: For | U1: Notes
A2: A01 | B2: A | C2: Measurement and safety | D2: Precision bench scale | E2: 3 kg capacity, 0.1 g resolution, tare. Weighs bodies, ballast and containers to 0.01 oz (0.28 g). | F2: 2 | G2: 15 | H2: USD | I2: =G2 -> 15 | J2: =F2*I2 -> 30 | K2: =I2*'Read me'!$B$4 -> 4.6624 | L2: =F2*K2 -> 9.3249 | M2: Buy now | N2: Estimate | Q2: 2026-10-09 | S2: 2026-10-11 | T2: TC-01, TC-02, TC-04 | U2: Example model: Duratool D03412 (3 kg × 0.1 g).
A3: A02 | B3: A | C3: Measurement and safety | D3: Digital hanging scale | E3: 50 kg × 10 g with hold function. Tension check; weighing payload bundles and airframes. | F3: 1 | G3: 15 | H3: USD | I3: =G3 -> 15 | J3: =F3*I3 -> 15 | K3: =I3*'Read me'!$B$4 -> 4.6624 | L3: =F3*K3 -> 4.6624 | M3: Buy now | N3: Estimate | Q3: 2026-10-09 | S3: 2026-10-11 | T3: TC-01, TC-04
A4: A03 | B4: A | C4: Measurement and safety | D4: Vane anemometer | E4: Handheld, 0.3–30 m/s, reads m/s and ft/min. | F4: 1 | G4: 26.99 | H4: USD | I4: =G4 -> 26.99 | J4: =F4*I4 -> 26.99 | K4: =I4*'Read me'!$B$4 -> 8.3893 | L4: =F4*K4 -> 8.3893 | M4: Buy now | N4: Listing | O4: HoldPeak HP-866B (eBay) | P4: https://www.ebay.ca/p/10014711598 | Q4: 2026-10-09 | R4: Search result | S4: 2026-10-11 | T4: TC-01 | U4: Upper limit 30 m/s (98 ft/s).
A5: A04 | B5: A | C5: Measurement and safety | D5: Digital caliper | E5: 150 mm, 0.01 mm. Foam thickness and permanent set; simulator size match (±1/8 in). Skip if the lab has one. | F5: 1 | G5: 20 | H5: USD | I5: =G5 -> 20 | J5: =F5*I5 -> 20 | K5: =I5*'Read me'!$B$4 -> 6.2166 | L5: =F5*K5 -> 6.2166 | M5: Buy now | N5: Estimate | Q5: 2026-10-09 | S5: 2026-10-11 | T5: TC-02, §3.1.3
A6: A05 | B6: A | C6: Measurement and safety | D6: Safety glasses | E6: Impact-rated (ANSI Z87.1 or EN 166). | F6: 6 | G6: 4 | H6: USD | I6: =G6 -> 4 | J6: =F6*I6 -> 24 | K6: =I6*'Read me'!$B$4 -> 1.2433 | L6: =F6*K6 -> 7.4599 | M6: Buy now | N6: Estimate | Q6: 2026-10-09 | S6: 2026-10-11 | T6: TC-01, TC-02
A7: A06 | B7: A | C7: Measurement and safety | D7: Earmuffs | E7: Passive hearing protection for blower runs. | F7: 3 | G7: 12 | H7: USD | I7: =G7 -> 12 | J7: =F7*I7 -> 36 | K7: =I7*'Read me'!$B$4 -> 3.7299 | L7: =F7*K7 -> 11.1898 | M7: Buy now | N7: Estimate | Q7: 2026-10-09 | S7: 2026-10-11 | T7: TC-01
A8: A07 | B8: A | C8: TC-01 blower rig | D8: Leaf blower | E8: Highest air volume available locally; target ≥ 15 m³/min (530 cfm). 230 V / 50 Hz or cordless; variable speed preferred. | F8: 1 | G8: 359 | H8: USD | I8: =G8 -> 359 | J8: =F8*I8 -> 359 | K8: =I8*'Read me'!$B$4 -> 111.5876 | L8: =F8*K8 -> 111.5876 | M8: Buy now | N8: Listing | O8: EGO LB7654, 765 cfm, 56 V kit (Ace Hardware) | P8: https://www.acehardware.com/departments/lawn-and-garden/outdoor-power-equipment/leaf-blowers/7026058 | Q8: 2026-10-09 | R8: Search result | S8: 2026-10-11 | T8: TC-01 | U8: US reference model. Buy the local equivalent and check its air-volume rating.
A9: A08 | B9: A | C9: TC-01 blower rig | D9: Duct and adapters | E9: Rigid round duct, 100 mm and 150 mm × 1 m; reducer to the blower nozzle; aluminium tape; clamps. | F9: 1 | G9: 40 | H9: USD | I9: =G9 -> 40 | J9: =F9*I9 -> 40 | K9: =I9*'Read me'!$B$4 -> 12.4332 | L9: =F9*K9 -> 12.4332 | M9: Buy now | N9: Estimate | Q9: 2026-10-09 | S9: 2026-10-11 | T9: TC-01
A10: A09 | B10: A | C10: TC-01 blower rig | D10: Drinking straws | E10: Plain straight straws, about 6–8 mm × 200 mm, for the flow straightener. | F10: 1 | G10: 10 | H10: USD | I10: =G10 -> 10 | J10: =F10*I10 -> 10 | K10: =I10*'Read me'!$B$4 -> 3.1083 | L10: =F10*K10 -> 3.1083 | M10: Buy now | N10: Estimate | Q10: 2026-10-09 | S10: 2026-10-11 | T10: TC-01 | U10: About 500 straws.
A11: A10 | B11: A | C11: TC-01 blower rig | D11: Ball-bearing swivels | E11: Fishing ball-bearing swivels, ≥ 50 lb rated. | F11: 10 | G11: 1.2 | H11: USD | I11: =G11 -> 1.2 | J11: =F11*I11 -> 12 | K11: =I11*'Read me'!$B$4 -> 0.373 | L11: =F11*K11 -> 3.7299 | M11: Buy now | N11: Estimate | Q11: 2026-10-09 | S11: 2026-10-11 | T11: TC-01 | U11: A swivel lets any roll tendency show as rotation.
A12: A11 | B12: A | C12: TC-01 blower rig | D12: Braided PE line | E12: 50–80 lb braided PE (Dyneema-type) fishing line, ≥ 150 yd. | F12: 1 | G12: 20 | H12: USD | I12: =G12 -> 20 | J12: =F12*I12 -> 20 | K12: =I12*'Read me'!$B$4 -> 6.2166 | L12: =F12*K12 -> 6.2166 | M12: Buy now | N12: Estimate | Q12: 2026-10-09 | S12: 2026-10-11 | T12: TC-01, TC-02, tow-line candidate
A13: A12 | B13: A | C13: TC-01 blower rig | D13: Ballast assortment | E13: Steel nuts and washers M5–M10 and lead-free sinkers, about 1 kg. | F13: 1 | G13: 15 | H13: USD | I13: =G13 -> 15 | J13: =F13*I13 -> 15 | K13: =I13*'Read me'!$B$4 -> 4.6624 | L13: =F13*K13 -> 4.6624 | M13: Buy now | N13: Estimate | Q13: 2026-10-09 | S13: 2026-10-11 | T13: TC-01, TC-02 | U13: Ballast must be internal to the sensor (§3.1.1).
A14: A13 | B14: A | C14: TC-02 drop test | D14: Foam sheet assortment | E14: At least 4 types: EPE (2 densities), EPS (2 densities), XPS, open-cell PU, EVA; 10, 20, 25 and 50 mm; about 0.5 m² per type and thickness. | F14: 1 | G14: 120 | H14: USD | I14: =G14 -> 120 | J14: =F14*I14 -> 120 | K14: =I14*'Read me'!$B$4 -> 37.2995 | L14: =F14*K14 -> 37.2995 | M14: Buy now | N14: Estimate | Q14: 2026-10-09 | S14: 2026-10-11 | T14: TC-02, Script 5 | U14: Ask each supplier for density and the compressive stress–strain curve (crush stress, densification strain).
A15: A14 | B15: A | C15: TC-02 drop test | D15: Plywood and MDF sheets | E15: 3 mm and 6 mm, laser-cutter bed size. | F15: 6 | G15: 8 | H15: USD | I15: =G15 -> 8 | J15: =F15*I15 -> 48 | K15: =I15*'Read me'!$B$4 -> 2.4866 | L15: =F15*K15 -> 14.9198 | M15: Buy now | N15: Estimate | Q15: 2026-10-09 | S15: 2026-10-11 | T15: TC-02 containers and fixture
A16: A15 | B16: A | C16: TC-02 drop test | D16: Brass rod | E16: 1/4 in (6.35 mm) brass, 300 mm long, for the quick-release pin replica. 6 mm metric is acceptable for testing. | F16: 2 | G16: 6 | H16: USD | I16: =G16 -> 6 | J16: =F16*I16 -> 12 | K16: =I16*'Read me'!$B$4 -> 1.865 | L16: =F16*K16 -> 3.7299 | M16: Buy now | N16: Estimate | Q16: 2026-10-09 | S16: 2026-10-11 | T16: TC-02 | U16: The contest pin is 1/4 in brass (§3.1.3).
A17: A16 | B17: A | C17: TC-02 drop test | D17: Welded steel rings | E17: Welded (not split) stainless rings, wire diameter ≤ 3.0 mm, inside diameter ≥ 13 mm. | F17: 10 | G17: 1 | H17: USD | I17: =G17 -> 1 | J17: =F17*I17 -> 10 | K17: =I17*'Read me'!$B$4 -> 0.3108 | L17: =F17*K17 -> 3.1083 | M17: Buy now | N17: Estimate | Q17: 2026-10-09 | S17: 2026-10-11 | T17: TC-02, TC-04 | U17: Rule: ID ≥ 1/2 in (12.7 mm), cross-section ≤ 1/8 in (3.18 mm) (§3.1.3).
A18: A17 | B18: A | C18: TC-02 drop test | D18: Rigging hardware assortment | E18: Mini stainless snap hooks, quick links, ball-lock quick-release pins, crimp sleeves. | F18: 1 | G18: 30 | H18: USD | I18: =G18 -> 30 | J18: =F18*I18 -> 30 | K18: =I18*'Read me'!$B$4 -> 9.3249 | L18: =F18*K18 -> 9.3249 | M18: Buy now | N18: Estimate | Q18: 2026-10-09 | S18: 2026-10-11 | T18: TC-02, TC-04, SR-10
A19: A18 | B19: A | C19: TC-02 drop test | D19: High-g accelerometer (optional) | E19: Adafruit H3LIS331 ±400 g breakout (product 4627), logged by a Pico (A24). | F19: 1 | G19: 24.95 | H19: USD | I19: =G19 -> 24.95 | J19: =F19*I19 -> 24.95 | K19: =I19*'Read me'!$B$4 -> 7.7552 | L19: =F19*K19 -> 7.7552 | M19: Buy now | N19: Listing | O19: Adafruit | P19: https://www.adafruit.com/product/4627 | Q19: 2026-10-09 | R19: Vendor page | S19: 2026-10-14 | T19: TC-02 peak g | U19: Optional. Without it, TC-02 still runs on damage checks and foam set.
A20: A19 | B20: A | C20: TC-03 lights | D20: Colour LED stars | E20: Cree XP-E2 single-emitter 20 mm star: red, red-orange, amber (1000 mA max). | F20: 6 | G20: 5.71 | H20: USD | I20: =G20 -> 5.71 | J20: =F20*I20 -> 34.26 | K20: =I20*'Read me'!$B$4 -> 1.7748 | L20: =F20*K20 -> 10.649 | M20: Buy now | N20: Listing | O20: LEDSupply (regular price; 0 in stock on 9 Oct) | P20: https://www.ledsupply.com/leds/cree-xlamp-xp-e2-color-high-power-led-star | Q20: 2026-10-09 | R20: Search result | S20: 2026-10-14 | T20: TC-03
A21: A20 | B21: A | C21: TC-03 lights | D21: White LED stars | E21: Cree XP-E2 or XP-G white, 20 mm star. | F21: 4 | G21: 6 | H21: USD | I21: =G21 -> 6 | J21: =F21*I21 -> 24 | K21: =I21*'Read me'!$B$4 -> 1.865 | L21: =F21*K21 -> 7.4599 | M21: Buy now | N21: Estimate | Q21: 2026-10-09 | S21: 2026-10-14 | T21: TC-03
A22: A21 | B22: A | C22: TC-03 lights | D22: LED optics | E22: 20 mm star optics, narrow (about 15°) and medium (about 30°). | F22: 8 | G22: 2 | H22: USD | I22: =G22 -> 2 | J22: =F22*I22 -> 16 | K22: =I22*'Read me'!$B$4 -> 0.6217 | L22: =F22*K22 -> 4.9733 | M22: Buy now | N22: Estimate | Q22: 2026-10-09 | S22: 2026-10-14 | T22: TC-03
A23: A22 | B23: A | C23: TC-03 lights | D23: Constant-current LED drivers | E23: 350–700 mA buck modules with a PWM dimming input. | F23: 6 | G23: 3 | H23: USD | I23: =G23 -> 3 | J23: =F23*I23 -> 18 | K23: =I23*'Read me'!$B$4 -> 0.9325 | L23: =F23*K23 -> 5.5949 | M23: Buy now | N23: Estimate | Q23: 2026-10-09 | S23: 2026-10-14 | T23: TC-03
A24: A23 | B24: A | C24: TC-03 lights | D24: 5 mm LEDs and LED strip | E24: Ultra-bright 5 mm assortment (white, red, amber, green); 5 V SMD strip, 1 m each of white and red. | F24: 1 | G24: 20 | H24: USD | I24: =G24 -> 20 | J24: =F24*I24 -> 20 | K24: =I24*'Read me'!$B$4 -> 6.2166 | L24: =F24*K24 -> 6.2166 | M24: Buy now | N24: Estimate | Q24: 2026-10-09 | S24: 2026-10-14 | T24: TC-03
A25: A24 | B25: A | C25: EE bench | D25: Microcontroller boards | E25: Raspberry Pi Pico (RP2040): TC-03 flash-pattern driver, test-box prototype, A18 logger. | F25: 4 | G25: 4 | H25: USD | I25: =G25 -> 4 | J25: =F25*I25 -> 16 | K25: =I25*'Read me'!$B$4 -> 1.2433 | L25: =F25*K25 -> 4.9733 | M25: Buy now | N25: Listing | O25: Raspberry Pi (list price) | P25: https://www.raspberrypi.com/products/raspberry-pi-pico/ | Q25: 2026-10-09 | R25: Vendor page | S25: 2026-10-14 | T25: TC-03, EE lane
A26: A25 | B26: A | C26: EE bench | D26: 1S LiPo packs, labelled | E26: COTS 1S LiPo, 300–1000 mAh; the label shows chemistry, capacity, voltage and C-rating. | F26: 4 | G26: 8 | H26: USD | I26: =G26 -> 8 | J26: =F26*I26 -> 32 | K26: =I26*'Read me'!$B$4 -> 2.4866 | L26: =F26*K26 -> 9.9465 | M26: Buy now | N26: Estimate | Q26: 2026-10-09 | S26: 2026-10-14 | T26: TC-03, sensor battery | U26: The sensor battery must meet §3.2.3 (§3.1.1).
A27: A26 | B27: A | C27: EE bench | D27: 1S LiPo charger | E27: USB charger for the A25 packs. | F27: 1 | G27: 12 | H27: USD | I27: =G27 -> 12 | J27: =F27*I27 -> 12 | K27: =I27*'Read me'!$B$4 -> 3.7299 | L27: =F27*K27 -> 3.7299 | M27: Buy now | N27: Estimate | Q27: 2026-10-09 | S27: 2026-10-14 | T27: TC-03
A28: A27 | B28: A | C28: EE bench | D28: Inline current meter | E28: USB / DC power meter, 0–5 A, 3–30 V. | F28: 1 | G28: 15 | H28: USD | I28: =G28 -> 15 | J28: =F28*I28 -> 15 | K28: =I28*'Read me'!$B$4 -> 4.6624 | L28: =F28*K28 -> 4.6624 | M28: Buy now | N28: Estimate | Q28: 2026-10-09 | S28: 2026-10-14 | T28: TC-03
A29: A28 | B29: A | C29: EE bench | D29: Electronics consumables | E29: Logic-level MOSFETs, resistor kit, perfboard, 26–30 AWG silicone wire, heat-shrink, breadboard, jumpers. | F29: 1 | G29: 35 | H29: USD | I29: =G29 -> 35 | J29: =F29*I29 -> 35 | K29: =I29*'Read me'!$B$4 -> 10.879 | L29: =F29*K29 -> 10.879 | M29: Buy now | N29: Estimate | Q29: 2026-10-09 | S29: 2026-10-14 | T29: TC-03, EE lane
A30: A29 | B30: A | C30: Fabrication and mock-ups | D30: PLA filament | E30: 1.75 mm, 1 kg. | F30: 3 | G30: 23 | H30: USD | I30: =G30 -> 23 | J30: =F30*I30 -> 69 | K30: =I30*'Read me'!$B$4 -> 7.1491 | L30: =F30*K30 -> 21.4472 | M30: Buy now | N30: Estimate | Q30: 2026-10-09 | S30: 2026-10-11 | T30: TC-01 bodies, TC-02 dummies, rig adapters | U30: Bambu Lab PLA Basic seen at USD 19.99–22.99 in regional stores (search, 9 Oct).
A31: A30 | B31: A | C31: Fabrication and mock-ups | D31: PETG filament | E31: 1.75 mm, 1 kg. | F31: 2 | G31: 23 | H31: USD | I31: =G31 -> 23 | J31: =F31*I31 -> 46 | K31: =I31*'Read me'!$B$4 -> 7.1491 | L31: =F31*K31 -> 14.2981 | M31: Buy now | N31: Estimate | Q31: 2026-10-09 | S31: 2026-10-11 | T31: Containers, fixtures
A32: A31 | B32: A | C32: Fabrication and mock-ups | D32: TPU 95A filament | E32: 1.75 mm, 1 kg. | F32: 1 | G32: 40 | H32: USD | I32: =G32 -> 40 | J32: =F32*I32 -> 40 | K32: =I32*'Read me'!$B$4 -> 12.4332 | L32: =F32*K32 -> 12.4332 | M32: Buy now | N32: Estimate | Q32: 2026-10-09 | S32: 2026-10-14 | T32: Bumpers, liner trials
A33: A32 | B33: A | C33: Fabrication and mock-ups | D33: Hatch-latch candidates | E33: Spring latches, R-clips and cotter pins, toggle latches, screw latches. | F33: 1 | G33: 25 | H33: USD | I33: =G33 -> 25 | J33: =F33*I33 -> 25 | K33: =I33*'Read me'!$B$4 -> 7.7707 | L33: =F33*K33 -> 7.7707 | M33: Buy now | N33: Estimate | Q33: 2026-10-09 | S33: 2026-10-14 | T33: TC-04, SR-04, SR-12 | U33: Magnets are not an acceptable latching method (§4.2.1).
A34: A33 | B34: A | C34: Fabrication and mock-ups | D34: Mock-up materials | E34: Cardboard sheets, hot-glue sticks, tape, paint markers (TOP / O / E markings, roll stripes). | F34: 1 | G34: 25 | H34: USD | I34: =G34 -> 25 | J34: =F34*I34 -> 25 | K34: =I34*'Read me'!$B$4 -> 7.7707 | L34: =F34*K34 -> 7.7707 | M34: Buy now | N34: Estimate | Q34: 2026-10-09 | S34: 2026-10-11 | T34: TC-01, TC-04
A35: B01 | B35: B | C35: Radio (ExpressLRS) | D35: ELRS transmitter | E35: RadioMaster Boxer, internal ELRS 2.4 GHz, FCC version, EdgeTX. Skip if the pilot already owns a radio with internal ELRS 2.4 GHz. | F35: 1 | G35: 153.99 | H35: USD | I35: =G35 -> 153.99 | J35: =F35*I35 -> 153.99 | K35: =I35*'Read me'!$B$4 -> 47.8646 | L35: =F35*K35 -> 47.8646 | M35: Buy now | N35: Listing | O35: RadioMaster | P35: https://radiomasterrc.com/products/boxer-radio-controller-m2 | Q35: 2026-10-09 | R35: Vendor page | S35: 2026-11-01 | T35: §3.2.1, §4.2.5 | U35: Transmitter cells are not included (B02).
A36: B02 | B36: B | C36: Radio (ExpressLRS) | D36: Transmitter cells | E36: 2 × 18650 Li-ion cells and a charger, for B01. | F36: 1 | G36: 20 | H36: USD | I36: =G36 -> 20 | J36: =F36*I36 -> 20 | K36: =I36*'Read me'!$B$4 -> 6.2166 | L36: =F36*K36 -> 6.2166 | M36: Buy now | N36: Estimate | Q36: 2026-10-09 | S36: 2026-11-01 | T36: B01
A37: B03 | B37: B | C37: Radio (ExpressLRS) | D37: ELRS PWM receiver, 8 ch | E37: RadioMaster ER8: 8 PWM outputs, 4.5–8.4 V, ELRS 3.3.0, FCC firmware. PWM output only: no CRSF-only receivers, which need a flight controller. | F37: 3 | G37: 34.99 | H37: USD | I37: =G37 -> 34.99 | J37: =F37*I37 -> 104.97 | K37: =I37*'Read me'!$B$4 -> 10.8759 | L37: =F37*K37 -> 32.6277 | M37: Buy now | N37: Listing | O37: RadioMaster | P37: https://radiomasterrc.com/products/er8-2-4ghz-elrs-pwm-receiver | Q37: 2026-10-09 | R37: Vendor page | S37: 2026-11-01 | T37: §3.2.1, §4.2.1, §4.2.5 | U37: One per airframe plus a spare. Fail-safe positions must be set in the receiver WebUI (default is centred).
A38: B04 | B38: B | C38: Radio (ExpressLRS) | D38: ELRS PWM receiver, 6 ch | E38: RadioMaster ER6: bench receiver for sensor and reel development, or the observer's payload link (§3.1). | F38: 1 | G38: 24.99 | H38: USD | I38: =G38 -> 24.99 | J38: =F38*I38 -> 24.99 | K38: =I38*'Read me'!$B$4 -> 7.7676 | L38: =F38*K38 -> 7.7676 | M38: Buy now | N38: Listing | O38: RadioMaster | P38: https://radiomasterrc.com/products/er6-2-4ghz-elrs-pwm-receiver | Q38: 2026-10-09 | R38: Vendor page | S38: 2026-11-01 | T38: EE lane, §3.1
A39: B05 | B39: B | C39: Radio (ExpressLRS) | D39: Receiver and servo battery | E39: 2S LiFe 6.6 V (7.2 V full), about 1450 mAh, COTS with label. | F39: 3 | G39: 34.99 | H39: USD | I39: =G39 -> 34.99 | J39: =F39*I39 -> 104.97 | K39: =I39*'Read me'!$B$4 -> 10.8759 | L39: =F39*K39 -> 32.6277 | M39: Buy now | N39: Listing | O39: Spektrum SPMB1450LFRX (Gator RC; out of stock on 9 Oct) | P39: https://www.gator-rc.com/products/spektrum-1450-receiver-battery | Q39: 2026-10-09 | R39: Vendor page | S39: 2026-11-01 | T39: §3.2.3 | U39: A separate receiver battery is mandatory. 7.2 V full charge needs HV servos (B19).
A40: B06 | B40: B | C40: Radio (ExpressLRS) | D40: External receiver switch | E40: Heavy-duty switch harness, mounted outside the airplane. An arming plug does not count as this switch. | F40: 3 | G40: 15 | H40: USD | I40: =G40 -> 15 | J40: =F40*I40 -> 45 | K40: =I40*'Read me'!$B$4 -> 4.6624 | L40: =F40*K40 -> 13.9873 | M40: Buy now | N40: Estimate | Q40: 2026-10-09 | S40: 2026-11-01 | T40: §3.2.1
...

Sheet Read me
A1: PR-01 Initial purchase request: test supplies and long-lead hardware
A2: AIAA Design/Build/Fly 2026–27 · American University of the Middle East · Doc AUM-DBF-27-PR-001 · Rev A · 9 Oct 2026
A3: Generated by procurement/make_pr.py from procurement/pr01_items.csv. Edit the CSV, then run procurement/build.sh; this workbook and the PDF are rebuilt together.
A4: USD → KWD | B4: 0.310829 | C4: KWD per USD. currencyconvert.online, updated 2026-10-08 21:00 UTC (market rates). Replace with the CBK rate if purchasing requires it; every KWD cell follows this one.
A5: GBP → USD | B5: 1.3229 | C5: USD per GBP. currencyconvert.online, updated 2026-10-08 21:00 UTC (market rates).
A7: How to read the Items sheet
A8: Status, Buy now: the specification is fixed; order now.
A9: Status, Budget hold: the category and quantity are known, but the exact part follows the 13 Oct sizing gate (analysis Scripts 3–5). Reserve the budget now; part numbers follow on 14 Oct.
A10: Price basis, Listing: the vendor's listed price, checked on 9 Oct 2026 (URL in column P). Column R says whether it was read on the vendor page or taken from search results for that page, which can lag the live page. A reference, not a quote.
A11: Price basis, Estimate: a planning figure that has not been verified. Get a quote.
A12: Prices exclude shipping, duties and VAT unless the vendor column says otherwise.
A14: Purchasing constraints from the contest rules (2026–27 draft)
A15: Receivers: ExpressLRS 2.4 GHz with PWM outputs (team decision, 8 Oct 2026). Do not substitute CRSF-only receivers: they need a flight controller, and flight controllers are banned (§3.2.1, §4.2.1). Buy FCC firmware versions: the radio must use a legal US frequency (§3.2.1).
A16: Batteries: every pack (propulsion, receiver, sensor) must be commercial off-the-shelf, unaltered, with the manufacturer's label stating chemistry, capacity, voltage and C-rating (§3.2.3, §3.1.1). Propulsion packs ≤ 100 Wh each and ≤ 100 Wh in total (§3.2.3.2). Keep the original packaging: tech inspection checks it (§4.2.3).
A17: Charging sacks: commercial, unaltered, manufacturer-labelled (§3.2.3).
A18: Fuses: blade type in a separate harness; rating ≤ the pack's maximum continuous current, capped at 100 A (§3.2.3.1, §3.2.3.2).
A19: Arming plug: wire the same gauge as the pack leads or heavier (§3.2.2).
... A28: Travel to Tucson and aircraft freight: separate travel request. Contingency: set by the team lead.
